{
 "cells": [
  {
   "cell_type": "markdown",
   "metadata": {},
   "source": [
    "## Exception Handling"
   ]
  },
  {
   "cell_type": "markdown",
   "metadata": {},
   "source": [
    ">* 예외는 오직 한 가지 일을 하는 함수의 한 부분이어야 합니다"
   ]
  },
  {
   "cell_type": "markdown",
   "metadata": {},
   "source": [
    "### Bad exception handling case"
   ]
  },
  {
   "cell_type": "code",
   "execution_count": 1,
   "metadata": {},
   "outputs": [],
   "source": [
    "class DataTransport:\n",
    "    \"\"\"An example of an object badly handling exceptions of different levels.\"\"\"\n",
    "\n",
    "    retry_threshold: int = 5\n",
    "    retry_n_times: int = 3\n",
    "\n",
    "    def __init__(self, connector):\n",
    "        self._connector = connector\n",
    "        self.connection = None\n",
    "\n",
    "    def deliver_event(self, event):\n",
    "        try:\n",
    "            self.connect()\n",
    "            data = event.decode()\n",
    "            self.send(data)\n",
    "        except ConnectionError as e:\n",
    "            logger.info(\"connection error detected: %s\", e)\n",
    "            raise\n",
    "        except ValueError as e:\n",
    "            logger.error(\"%r contains incorrect data: %s\", event, e)\n",
    "            raise\n",
    "\n",
    "    def connect(self):\n",
    "        for _ in range(self.retry_n_times):\n",
    "            try:\n",
    "                self.connection = self._connector.connect()\n",
    "            except ConnectionError as e:\n",
    "                logger.info(\n",
    "                    \"%s: attempting new connection in %is\",\n",
    "                    e,\n",
    "                    self.retry_threshold,\n",
    "                )\n",
    "                time.sleep(self.retry_threshold)\n",
    "            else:\n",
    "                return self.connection\n",
    "        raise ConnectionError(\n",
    "            f\"Couldn't connect after {self.retry_n_times} times\"\n",
    "        )\n",
    "\n",
    "    def send(self, data):\n",
    "        return self.connection.send(data)\n",
    "    "
   ]
  },
  {
   "cell_type": "markdown",
   "metadata": {},
   "source": [
    "* 위의 deliver_event()가 다루고 있는 두 개의 예외처리 (ConnectionError, ValueError)는 서로 관련이 없으며 에러 발생시 책임의 소재가 불분명하다\n",
    "* 따라서 각 예외처리는 세분화된 메소드로 나누어 그 안에서 다뤄지는 것이 옳다"
   ]
  },
  {
   "cell_type": "markdown",
   "metadata": {},
   "source": [
    "### Better exception handling case"
   ]
  },
  {
   "cell_type": "code",
   "execution_count": 2,
   "metadata": {},
   "outputs": [],
   "source": [
    "def connect_with_retry(connector, retry_n_times, retry_threshold=5):\n",
    "    \"\"\"Tries to establish the connection of <connector> retrying\n",
    "    <retry_n_times>.\n",
    "\n",
    "    If it can connect, returns the connection object.\n",
    "    If it's not possible after the retries, raises ConnectionError\n",
    "\n",
    "    :param connector:           An object with a `.connect()` method.\n",
    "    :param retry_n_times int:   The number of times to try to call\n",
    "                                ``connector.connect()``.\n",
    "    :param retry_threshold int: The time lapse between retry calls.\n",
    "\n",
    "    \"\"\"\n",
    "    for _ in range(retry_n_times):\n",
    "        try:\n",
    "            return connector.connect()\n",
    "        except ConnectionError as e:\n",
    "            logger.info(\n",
    "                \"%s: attempting new connection in %is\", e, retry_threshold\n",
    "            )\n",
    "            time.sleep(retry_threshold)\n",
    "    exc = ConnectionError(f\"Couldn't connect after {retry_n_times} times\")\n",
    "    logger.exception(exc)\n",
    "    raise exc\n",
    "\n",
    "\n",
    "class DataTransport:\n",
    "    \"\"\"An example of an object that separates the exception handling by\n",
    "    abstraction levels.\n",
    "    \"\"\"\n",
    "\n",
    "    retry_threshold: int = 5\n",
    "    retry_n_times: int = 3\n",
    "\n",
    "    def __init__(self, connector):\n",
    "        self._connector = connector\n",
    "        self.connection = None\n",
    "\n",
    "    def deliver_event(self, event):\n",
    "        self.connection = connect_with_retry(\n",
    "            self._connector, self.retry_n_times, self.retry_threshold\n",
    "        )\n",
    "        self.send(event)\n",
    "\n",
    "    def send(self, event):\n",
    "        try:\n",
    "            return self.connection.send(event.decode())\n",
    "        except ValueError as e:\n",
    "            logger.error(\"%r contains incorrect data: %s\", event, e)\n",
    "            raise"
   ]
  },
  {
   "cell_type": "markdown",
   "metadata": {},
   "source": [
    "* 위의 코드에서 ConnectionError는 연결 구현 부분인 connect_with_retry()에서만 다뤄지며, ValueError는 보낼 event를 decode하는 send()에서만 다뤄진다\n",
    "* 에러 발생시 책임의 소재가 분명하다"
   ]
  },
  {
   "cell_type": "markdown",
   "metadata": {},
   "source": [
    "## Inheritance"
   ]
  },
  {
   "cell_type": "code",
   "execution_count": null,
   "metadata": {},
   "outputs": [],
   "source": []
  },
  {
   "cell_type": "markdown",
   "metadata": {},
   "source": [
    "## Keep it Simple (KIS)"
   ]
  },
  {
   "cell_type": "code",
   "execution_count": null,
   "metadata": {},
   "outputs": [],
   "source": []
  },
  {
   "cell_type": "markdown",
   "metadata": {},
   "source": [
    "## Orthogonality"
   ]
  },
  {
   "cell_type": "code",
   "execution_count": null,
   "metadata": {},
   "outputs": [],
   "source": []
  },
  {
   "cell_type": "code",
   "execution_count": null,
   "metadata": {},
   "outputs": [],
   "source": []
  }
 ],
 "metadata": {
  "kernelspec": {
   "display_name": "Tensorflow",
   "language": "python",
   "name": "tensorflow"
  },
  "language_info": {
   "codemirror_mode": {
    "name": "ipython",
    "version": 3
   },
   "file_extension": ".py",
   "mimetype": "text/x-python",
   "name": "python",
   "nbconvert_exporter": "python",
   "pygments_lexer": "ipython3",
   "version": "3.6.8"
  }
 },
 "nbformat": 4,
 "nbformat_minor": 2
}
